<?xml version="1.0"?>
<robot xmlns:xacro="http://www.ros.org/wiki/xacro">

  <link name="LEFTARM_1">
    <visual name="LEFTARM_1_visual">
      <origin xyz="-1.168 0.010 -0.346" rpy="-0.406350 -1.380610 -2.728595"/>
      <geometry>
        <mesh filename="package://kist_robot/meshes/left_arm/LEFTARM_1.stl" scale="0.001 0.001 0.001"/>
      </geometry>
      <material name="green"/>
    </visual>
    
    <collision name="LEFTARM_1_collision">
      <origin xyz="-1.168 0.010 -0.346" rpy="-0.406350 -1.380610 -2.728595"/>
      <geometry>
        <mesh filename="package://kist_robot/meshes/left_arm/LEFTARM_1.stl" scale="0.001 0.001 0.001"/>
      </geometry>
    </collision>
  </link>

  <link name="LEFTARM_SHELL_1">
    <visual name="LEFTARM_SHELL_1_visual">
      <origin xyz="-0.2 0.0 -1.1" rpy="0.0 0.0 3.14"/>
      <geometry>
        <mesh filename="package://kist_robot/meshes/left_arm/LEFTARM_SHELL_1.stl" scale="0.001 0.001 0.001"/>
      </geometry>
      <material name="blue"/>
    </visual>
    
    <collision name="LEFTARM_SHELL_1_collision">
      <origin xyz="-0.2 0.0 -1.1" rpy="0.0 0.0 3.14"/>
      <geometry>
        <mesh filename="package://kist_robot/meshes/left_arm/LEFTARM_SHELL_1.stl" scale="0.001 0.001 0.001"/>
      </geometry>
    </collision>
  </link>

  <link name="LEFTARM_2">
    <visual name="LEFTARM_2_visual">
      <origin xyz="-0.191 1.220 -0.057" rpy="1.570796 -0.075946 0.000"/>
      <geometry>
        <mesh filename="package://kist_robot/meshes/left_arm/LEFTARM_2.stl" scale="0.001 0.001 0.001"/>
      </geometry>
      <material name="green"/>
    </visual>
    
    <collision name="LEFTARM_2_collision">
      <origin xyz="-0.191 1.220 -0.057" rpy="1.570796 -0.075946 0.000"/>
      <geometry>
        <mesh filename="package://kist_robot/meshes/left_arm/LEFTARM_2.stl" scale="0.001 0.001 0.001"/>
      </geometry>
    </collision>
  </link>

  <link name="LEFTARM_3">
    <visual name="LEFTARM_3_visual">
      <origin xyz="-0.224 -0.017 -1.099" rpy="-0.000 0.000 0.075946"/>
      <geometry>
        <mesh filename="package://kist_robot/meshes/left_arm/LEFTARM_3.stl" scale="0.001 0.001 0.001"/>
      </geometry>
      <material name="green"/>
    </visual>
    
    <collision name="LEFTARM_3_collision">
      <origin xyz="-0.224 -0.017 -1.099" rpy="-0.000 0.000 0.075946"/>
      <geometry>
        <mesh filename="package://kist_robot/meshes/left_arm/LEFTARM_3.stl" scale="0.001 0.001 0.001"/>
      </geometry>
    </collision>
  </link>

  <link name="LEFTARM_4">
    <visual name="LEFTARM_4_visual">
      <origin xyz="-0.970 0.000 0.258" rpy="1.570796 1.494850 1.570796"/>
      <geometry>
        <mesh filename="package://kist_robot/meshes/left_arm/LEFTARM_4.stl" scale="0.001 0.001 0.001"/>
      </geometry>
      <material name="black"/>
    </visual>
    
    <collision name="LEFTARM_4_collision">
      <origin xyz="-0.970 0.000 0.258" rpy="1.570796 1.494850 1.570796"/>
      <geometry>
        <mesh filename="package://kist_robot/meshes/left_arm/LEFTARM_4.stl" scale="0.001 0.001 0.001"/>
      </geometry>
    </collision>
  </link>

  <link name="LEFTARM_5">
    <visual name="LEFTARM_5_visual">
      <origin xyz="-0.233 0.018 0.832" rpy="3.141593 0.000 -0.075946"/>
      <geometry>
        <mesh filename="package://kist_robot/meshes/left_arm/LEFTARM_5.stl" scale="0.001 0.001 0.001"/>
      </geometry>
      <material name="green"/>
    </visual>
    
    <collision name="LEFTARM_5_collision">
      <origin xyz="-0.233 0.018 0.832" rpy="3.141593 0.000 -0.075946"/>
      <geometry>
        <mesh filename="package://kist_robot/meshes/left_arm/LEFTARM_5.stl" scale="0.001 0.001 0.001"/>
      </geometry>
    </collision>
  </link>

  <link name="LEFT_HAND">
    <visual>
      <origin xyz="0.000 0.000 0.019" rpy="0.000 0.000 0.000"/>
      <geometry>
        <box size="0.03 0.10 0.10"/>
      </geometry>
      <material name="green"/>
    </visual>
    
    <collision name="LEFT_HAND_collision">
      <origin xyz="0.000 0.000 0.019" rpy="0.000 0.000 0.000"/>
      <geometry>
        <box size="0.03 0.10 0.10"/>
      </geometry>
    </collision>
  </link>

  <!-- Joints -->
  <joint name="UPBODY_leftarm_1" type="continuous">
    <origin xyz="0.137 -0.010 -0.060" rpy="3.141593 1.396263 3.141593"/>
    <parent link="UPBODY"/>
    <child link="LEFTARM_1"/>
    <axis xyz="-0.001 0.074721 -0.997204"/>
  </joint>

  <joint name="leftarm_1_shell_1" type="fixed">
    <origin xyz="0.0 0.0 0.0" rpy="0.0 0.0 0.0"/>
    <parent link="LEFTARM_3"/>
    <child link="LEFTARM_SHELL_1"/>
    <axis xyz="0.0 0.0 0.0"/>
  </joint>

  <joint name="UPBODY_leftarm_2" type="continuous">
    <origin xyz="0.001 -0.047 0.054" rpy="-1.570796 -1.396263 3.141593"/>
    <parent link="LEFTARM_1"/>
    <child link="LEFTARM_2"/>
    <axis xyz="-0.075873 0.000 0.997117"/>
  </joint>

  <joint name="UPBODY_leftarm_3" type="continuous">
    <origin xyz="0.033 0.121 -0.040" rpy="1.570796 0.000 0.000"/>
    <parent link="LEFTARM_2"/>
    <child link="LEFTARM_3"/>
    <axis xyz="0.0 0.0 1.0"/>
  </joint>

  <joint name="UPBODY_leftarm_4" type="continuous">
    <origin xyz="0.033 -0.018 -0.129" rpy="0.000 -1.570796 0.000"/>
    <parent link="LEFTARM_3"/>
    <child link="LEFTARM_4"/>
    <axis xyz="0.000 -0.075873 0.997117"/>
  </joint>

  <joint name="UPBODY_leftarm_5" type="continuous">
    <origin xyz="-0.138 0.018 0.025" rpy="3.141593 1.570796 0.000"/>
    <parent link="LEFTARM_4"/>
    <child link="LEFTARM_5"/>
    <axis xyz="0.0 0.0 -1.0"/>
  </joint>

  <joint name="left_hand" type="fixed">
    <origin xyz="0.000 0.000 0.075" rpy="0.000 0.000 0.000"/>
    <parent link="LEFTARM_5"/>
    <child link="LEFT_HAND"/>
  </joint>
</robot>